<sdf version='1.7'>
  <world name='default'>
    <light name='sun' type='directional'>
      <cast_shadows>1</cast_shadows>
      <pose>0 0 10 0 -0 0</pose>
      <diffuse>0.8 0.8 0.8 1</diffuse>
      <specular>0.2 0.2 0.2 1</specular>
      <attenuation>
        <range>1000</range>
        <constant>0.9</constant>
        <linear>0.01</linear>
        <quadratic>0.001</quadratic>
      </attenuation>
      <direction>-0.5 0.1 -0.9</direction>
      <spot>
        <inner_angle>0</inner_angle>
        <outer_angle>0</outer_angle>
        <falloff>0</falloff>
      </spot>
    </light>
    <model name='ground_plane'>
      <static>1</static>
      <link name='link'>
        <collision name='collision'>
          <geometry>
            <plane>
              <normal>0 0 1</normal>
              <size>100 100</size>
            </plane>
          </geometry>
          <surface>
            <contact>
              <collide_bitmask>65535</collide_bitmask>
              <ode/>
            </contact>
            <friction>
              <ode>
                <mu>100</mu>
                <mu2>50</mu2>
              </ode>
              <torsional>
                <ode/>
              </torsional>
            </friction>
            <bounce/>
          </surface>
          <max_contacts>10</max_contacts>
        </collision>
        <visual name='visual'>
          <cast_shadows>0</cast_shadows>
          <geometry>
            <plane>
              <normal>0 0 1</normal>
              <size>100 100</size>
            </plane>
          </geometry>
          <material>
            <script>
              <uri>file://media/materials/scripts/gazebo.material</uri>
              <name>Gazebo/Grey</name>
            </script>
          </material>
        </visual>
        <self_collide>0</self_collide>
        <enable_wind>0</enable_wind>
        <kinematic>0</kinematic>
      </link>
    </model>
    <gravity>0 0 -9.8</gravity>
    <magnetic_field>6e-06 2.3e-05 -4.2e-05</magnetic_field>
    <atmosphere type='adiabatic'/>
    <physics type='ode'>
      <max_step_size>0.001</max_step_size>
      <real_time_factor>1</real_time_factor>
      <real_time_update_rate>1000</real_time_update_rate>
    </physics>
    <scene>
      <ambient>0.4 0.4 0.4 1</ambient>
      <background>0.7 0.7 0.7 1</background>
      <shadows>1</shadows>
    </scene>
    <wind/>
    <spherical_coordinates>
      <surface_model>EARTH_WGS84</surface_model>
      <latitude_deg>0</latitude_deg>
      <longitude_deg>0</longitude_deg>
      <elevation>0</elevation>
      <heading_deg>0</heading_deg>
    </spherical_coordinates>
    <model name='Arena'>
      <pose>0.003059 0.015383 0 0 -0 0</pose>
      <link name='Wall_2'>
        <collision name='Wall_2_Collision'>
          <geometry>
            <box>
              <size>3.23208 0.15 0.304</size>
            </box>
          </geometry>
          <pose>0 0 0.152 0 -0 0</pose>
          <max_contacts>10</max_contacts>
          <surface>
            <contact>
              <ode/>
            </contact>
            <bounce/>
            <friction>
              <torsional>
                <ode/>
              </torsional>
              <ode/>
            </friction>
          </surface>
        </collision>
        <visual name='Wall_2_Visual'>
          <pose>0 0 0.152 0 -0 0</pose>
          <geometry>
            <box>
              <size>3.23208 0.15 0.304</size>
            </box>
          </geometry>
          <material>
            <script>
              <uri>file://media/materials/scripts/gazebo.material</uri>
              <name>Gazebo/Wood</name>
            </script>
            <ambient>1 1 1 1</ambient>
          </material>
          <meta>
            <layer>0</layer>
          </meta>
        </visual>
        <pose>0 1.735 0 0 -0 0</pose>
        <self_collide>0</self_collide>
        <enable_wind>0</enable_wind>
        <kinematic>0</kinematic>
      </link>
      <link name='Wall_3'>
        <collision name='Wall_3_Collision'>
          <geometry>
            <box>
              <size>3.62021 0.15 0.304</size>
            </box>
          </geometry>
          <pose>0 0 0.152 0 -0 0</pose>
          <max_contacts>10</max_contacts>
          <surface>
            <contact>
              <ode/>
            </contact>
            <bounce/>
            <friction>
              <torsional>
                <ode/>
              </torsional>
              <ode/>
            </friction>
          </surface>
        </collision>
        <visual name='Wall_3_Visual'>
          <pose>0 0 0.152 0 -0 0</pose>
          <geometry>
            <box>
              <size>3.62021 0.15 0.304</size>
            </box>
          </geometry>
          <material>
            <script>
              <uri>file://media/materials/scripts/gazebo.material</uri>
              <name>Gazebo/Wood</name>
            </script>
            <ambient>1 1 1 1</ambient>
          </material>
          <meta>
            <layer>0</layer>
          </meta>
        </visual>
        <pose>1.541 0 0 0 -0 -1.5708</pose>
        <self_collide>0</self_collide>
        <enable_wind>0</enable_wind>
        <kinematic>0</kinematic>
      </link>
      <link name='Wall_4'>
        <collision name='Wall_4_Collision'>
          <geometry>
            <box>
              <size>3.22 0.15 0.304</size>
            </box>
          </geometry>
          <pose>0 0 0.152 0 -0 0</pose>
          <max_contacts>10</max_contacts>
          <surface>
            <contact>
              <ode/>
            </contact>
            <bounce/>
            <friction>
              <torsional>
                <ode/>
              </torsional>
              <ode/>
            </friction>
          </surface>
        </collision>
        <visual name='Wall_4_Visual'>
          <pose>0 0 0.152 0 -0 0</pose>
          <geometry>
            <box>
              <size>3.22 0.15 0.304</size>
            </box>
          </geometry>
          <material>
            <script>
              <uri>file://media/materials/scripts/gazebo.material</uri>
              <name>Gazebo/Wood</name>
            </script>
            <ambient>1 1 1 1</ambient>
          </material>
          <meta>
            <layer>0</layer>
          </meta>
        </visual>
        <pose>0.006 -1.735 0 0 -0 3.14159</pose>
        <self_collide>0</self_collide>
        <enable_wind>0</enable_wind>
        <kinematic>0</kinematic>
      </link>
      <link name='Wall_5'>
        <collision name='Wall_5_Collision'>
          <geometry>
            <box>
              <size>3.62001 0.15 0.304</size>
            </box>
          </geometry>
          <pose>0 0 0.152 0 -0 0</pose>
          <max_contacts>10</max_contacts>
          <surface>
            <contact>
              <ode/>
            </contact>
            <bounce/>
            <friction>
              <torsional>
                <ode/>
              </torsional>
              <ode/>
            </friction>
          </surface>
        </collision>
        <visual name='Wall_5_Visual'>
          <pose>0 0 0.152 0 -0 0</pose>
          <geometry>
            <box>
              <size>3.62001 0.15 0.304</size>
            </box>
          </geometry>
          <material>
            <script>
              <uri>file://media/materials/scripts/gazebo.material</uri>
              <name>Gazebo/Wood</name>
            </script>
            <ambient>1 1 1 1</ambient>
          </material>
          <meta>
            <layer>0</layer>
          </meta>
        </visual>
        <pose>-1.529 0 0 0 -0 1.5708</pose>
        <self_collide>0</self_collide>
        <enable_wind>0</enable_wind>
        <kinematic>0</kinematic>
      </link>
      <static>1</static>
    </model>
    <state world_name='default'>
      <sim_time>43 936000000</sim_time>
      <real_time>0 0</real_time>
      <wall_time>1667913865 771885858</wall_time>
      <iterations>0</iterations>
      <model name='5x5_1000-1_0'>
        <pose>3.08811 -0.973743 0.007933 -1.35796 -1.55657 0.60558</pose>
        <scale>1 1 1</scale>
        <link name='link'>
          <pose>3.08811 -0.973743 0.007933 -1.35796 -1.55657 0.60558</pose>
          <velocity>0 0 0 0 -0 0</velocity>
          <acceleration>0 0 0 0 -0 0</acceleration>
          <wrench>0 0 0 0 -0 0</wrench>
        </link>
      </model>
      <model name='5x5_1000-2'>
        <pose>0.431617 -0.543827 0.093711 3.14159 -1.56626 3.14159</pose>
        <scale>1 1 1</scale>
        <link name='link'>
          <pose>0.431617 -0.543827 0.093711 3.14159 -1.56626 3.14159</pose>
          <velocity>0 0 0 0 -0 0</velocity>
          <acceleration>0 0 0 0 -0 0</acceleration>
          <wrench>0 0 0 0 -0 0</wrench>
        </link>
      </model>
      <model name='Arena'>
        <pose>0.040492 0.12637 0 0 -0 0</pose>
        <scale>1 1 1</scale>
        <link name='Wall_2'>
          <pose>0.040492 1.86137 0 0 -0 0</pose>
          <velocity>0 0 0 0 -0 0</velocity>
          <acceleration>0 0 0 0 -0 0</acceleration>
          <wrench>0 0 0 0 -0 0</wrench>
        </link>
        <link name='Wall_3'>
          <pose>1.58149 0.126378 0 0 0 -1.5708</pose>
          <velocity>0 0 0 0 -0 0</velocity>
          <acceleration>0 0 0 0 -0 0</acceleration>
          <wrench>0 0 0 0 -0 0</wrench>
        </link>
        <link name='Wall_4'>
          <pose>0.046492 -1.60863 0 0 -0 3.14159</pose>
          <velocity>0 0 0 0 -0 0</velocity>
          <acceleration>0 0 0 0 -0 0</acceleration>
          <wrench>0 0 0 0 -0 0</wrench>
        </link>
        <link name='Wall_5'>
          <pose>-1.48851 0.126378 0 0 -0 1.5708</pose>
          <velocity>0 0 0 0 -0 0</velocity>
          <acceleration>0 0 0 0 -0 0</acceleration>
          <wrench>0 0 0 0 -0 0</wrench>
        </link>
      </model>
      <model name='Drop_zone'>
        <pose>2.52948 -0.642349 0 0 -0 0</pose>
        <scale>1 1 1</scale>
        <link name='Wall_0'>
          <pose>2.73394 -0.665851 0 0 -0 0.784218</pose>
          <velocity>0 0 0 0 -0 0</velocity>
          <acceleration>0 0 0 0 -0 0</acceleration>
          <wrench>0 0 0 0 -0 0</wrench>
        </link>
        <link name='Wall_1'>
          <pose>3.16594 -0.662851 0 0 0 -0.758567</pose>
          <velocity>0 0 0 0 -0 0</velocity>
          <acceleration>0 0 0 0 -0 0</acceleration>
          <wrench>0 0 0 0 -0 0</wrench>
        </link>
        <link name='Wall_2'>
          <pose>3.17994 -1.08035 0 0 0 -2.34897</pose>
          <velocity>0 0 0 0 -0 0</velocity>
          <acceleration>0 0 0 0 -0 0</acceleration>
          <wrench>0 0 0 0 -0 0</wrench>
        </link>
        <link name='Wall_3'>
          <pose>2.75094 -1.08035 0 0 -0 2.38859</pose>
          <velocity>0 0 0 0 -0 0</velocity>
          <acceleration>0 0 0 0 -0 0</acceleration>
          <wrench>0 0 0 0 -0 0</wrench>
        </link>
      </model>
      <model name='Dropzone_base'>
        <pose>2.95451 -0.862279 0 0 -0 0</pose>
        <scale>1.08534 1.0047 1</scale>
        <link name='link_0'>
          <pose>2.95451 -0.862279 0 0 0 -0.755838</pose>
          <velocity>0 0 0 0 -0 0</velocity>
          <acceleration>0 0 0 0 -0 0</acceleration>
          <wrench>0 0 0 0 -0 0</wrench>
        </link>
      </model>
      <model name='Dropzone_base_clone'>
        <pose>0.105222 0.165822 0 0 -0 0.758678</pose>
        <scale>6.68949 8.28887 1</scale>
        <link name='link_0'>
          <pose>0.105222 0.165822 0 0 -0 0.00284</pose>
          <velocity>0 0 0 0 -0 0</velocity>
          <acceleration>0 0 0 0 -0 0</acceleration>
          <wrench>0 0 0 0 -0 0</wrench>
        </link>
      </model>
      <model name='Landing_pad'>
        <pose>3.00789 1.02999 0 0 -0 0</pose>
        <scale>1 1 1</scale>
        <link name='link_0'>
          <pose>3.00789 1.02999 0 0 -0 0</pose>
          <velocity>0 0 0 0 -0 0</velocity>
          <acceleration>0 0 0 0 -0 0</acceleration>
          <wrench>0 0 0 0 -0 0</wrench>
        </link>
      </model>
      <model name='Package1'>
        <pose>0.334419 -0.543897 0.042023 0 -0 0</pose>
        <scale>3.20965 3.30741 1</scale>
        <link name='link_0'>
          <pose>0.334419 -0.543897 0.042023 0 -0 0</pose>
          <velocity>0 0 0 0 -0 0</velocity>
          <acceleration>0 0 0 0 -0 0</acceleration>
          <wrench>0 0 0 0 -0 0</wrench>
        </link>
      </model>
      <model name='Package2'>
        <pose>-0.144962 -0.800638 0 0 -0 0</pose>
        <scale>1 1 1</scale>
        <link name='link_1'>
          <pose>-0.144962 -0.800638 0 0 -0 0</pose>
          <velocity>0 0 0 0 -0 0</velocity>
          <acceleration>0 0 0 0 -0 0</acceleration>
          <wrench>0 0 0 0 -0 0</wrench>
        </link>
      </model>
      <model name='ground_plane'>
        <pose>0 0 0 0 -0 0</pose>
        <scale>1 1 1</scale>
        <link name='link'>
          <pose>0 0 0 0 -0 0</pose>
          <velocity>0 0 0 0 -0 0</velocity>
          <acceleration>0 0 0 0 -0 0</acceleration>
          <wrench>0 0 0 0 -0 0</wrench>
        </link>
      </model>
      <model name='iris'>
        <pose>3.00534 0.999303 0 0 -0 0</pose>
        <scale>1 1 1</scale>
        <link name='camera'>
          <pose>3.00534 0.989303 0.07 1.57 -0 1.57</pose>
          <velocity>0 0 0 0 -0 0</velocity>
          <acceleration>0 0 0 0 -0 0</acceleration>
          <wrench>0 0 0 0 -0 0</wrench>
        </link>
        <link name='iris_demo::gimbal_small_2d::base_link'>
          <pose>3.00534 0.989303 0.07 1.57 -0 1.57</pose>
          <velocity>0 0 0 0 -0 0</velocity>
          <acceleration>0 0 0 0 -0 0</acceleration>
          <wrench>0 0 0 0 -0 0</wrench>
        </link>
        <link name='iris_demo::gimbal_small_2d::tilt_link'>
          <pose>3.00534 0.989303 0.07 3.14 0 1.57</pose>
          <velocity>0 0 0 0 -0 0</velocity>
          <acceleration>0 0 0 0 -0 0</acceleration>
          <wrench>0 0 0 0 -0 0</wrench>
        </link>
        <link name='iris_demo::iris::base_link'>
          <pose>3.00534 0.999303 0.194923 0 -0 0</pose>
          <velocity>0 0 0 0 -0 0</velocity>
          <acceleration>0 0 0 0 -0 0</acceleration>
          <wrench>0 0 0 0 -0 0</wrench>
        </link>
        <link name='iris_demo::iris::iris/ground_truth/odometry_sensorgt_link'>
          <pose>3.00534 0.999303 0.194923 0 -0 0</pose>
          <velocity>0 0 0 0 -0 0</velocity>
          <acceleration>0 0 0 0 -0 0</acceleration>
          <wrench>0 0 0 0 -0 0</wrench>
        </link>
        <link name='iris_demo::iris::iris/imu_link'>
          <pose>3.00534 0.999303 0.194923 0 -0 0</pose>
          <velocity>0 0 0 0 -0 0</velocity>
          <acceleration>0 0 0 0 -0 0</acceleration>
          <wrench>0 0 0 0 -0 0</wrench>
        </link>
        <link name='iris_demo::iris::rotor_0'>
          <pose>3.13534 0.779303 0.217923 0 -0 0</pose>
          <velocity>0 0 0 0 -0 0</velocity>
          <acceleration>0 0 0 0 -0 0</acceleration>
          <wrench>0 0 0 0 -0 0</wrench>
        </link>
        <link name='iris_demo::iris::rotor_1'>
          <pose>2.87534 1.1993 0.217923 0 -0 0</pose>
          <velocity>0 0 0 0 -0 0</velocity>
          <acceleration>0 0 0 0 -0 0</acceleration>
          <wrench>0 0 0 0 -0 0</wrench>
        </link>
        <link name='iris_demo::iris::rotor_2'>
          <pose>3.13534 1.2193 0.217923 0 -0 0</pose>
          <velocity>0 0 0 0 -0 0</velocity>
          <acceleration>0 0 0 0 -0 0</acceleration>
          <wrench>0 0 0 0 -0 0</wrench>
        </link>
        <link name='iris_demo::iris::rotor_3'>
          <pose>2.87534 0.799303 0.217923 0 -0 0</pose>
          <velocity>0 0 0 0 -0 0</velocity>
          <acceleration>0 0 0 0 -0 0</acceleration>
          <wrench>0 0 0 0 -0 0</wrench>
        </link>
      </model>
      <light name='sun'>
        <pose>0 0 10 0 -0 0</pose>
      </light>
    </state>
    <gui fullscreen='0'>
      <camera name='user_camera'>
        <pose>0.118906 -5.14734 10.8248 -0 1.03759 1.31639</pose>
        <view_controller>orbit</view_controller>
        <projection_type>perspective</projection_type>
      </camera>
    </gui>
    <model name='Package1'>
      <link name='link_0'>
        <inertial>
          <mass>1</mass>
          <inertia>
            <ixx>0.166667</ixx>
            <ixy>0</ixy>
            <ixz>0</ixz>
            <iyy>0.166667</iyy>
            <iyz>0</iyz>
            <izz>0.166667</izz>
          </inertia>
          <pose>0 0 0 0 -0 0</pose>
        </inertial>
        <pose>-0 0 0 0 -0 0</pose>
        <gravity>1</gravity>
        <self_collide>0</self_collide>
        <kinematic>0</kinematic>
        <enable_wind>0</enable_wind>
        <visual name='visual'>
          <pose>0 0 0 0 -0 0</pose>
          <geometry>
            <box>
              <size>0.0762 0.0762 0.0762</size>
            </box>
          </geometry>
          <material>
            <lighting>1</lighting>
            <script>
              <uri>file://media/materials/scripts/gazebo.material</uri>
              <name>Gazebo/Grey</name>
            </script>
            <shader type='pixel'>
              <normal_map>__default__</normal_map>
            </shader>
            <ambient>0.3 0.3 0.3 1</ambient>
            <diffuse>0.7 0.7 0.7 1</diffuse>
            <specular>0.01 0.01 0.01 1</specular>
            <emissive>0 0 0 1</emissive>
          </material>
          <transparency>0</transparency>
          <cast_shadows>1</cast_shadows>
        </visual>
        <collision name='collision'>
          <laser_retro>0</laser_retro>
          <max_contacts>10</max_contacts>
          <pose>0 0 0 0 -0 0</pose>
          <geometry>
            <box>
              <size>0.0762 0.0762 0.0762</size>
            </box>
          </geometry>
          <surface>
            <friction>
              <ode>
                <mu>1</mu>
                <mu2>1</mu2>
                <fdir1>0 0 0</fdir1>
                <slip1>0</slip1>
                <slip2>0</slip2>
              </ode>
              <torsional>
                <coefficient>1</coefficient>
                <patch_radius>0</patch_radius>
                <surface_radius>0</surface_radius>
                <use_patch_radius>1</use_patch_radius>
                <ode>
                  <slip>0</slip>
                </ode>
              </torsional>
            </friction>
            <bounce>
              <restitution_coefficient>0</restitution_coefficient>
              <threshold>1e+06</threshold>
            </bounce>
            <contact>
              <collide_without_contact>0</collide_without_contact>
              <collide_without_contact_bitmask>1</collide_without_contact_bitmask>
              <collide_bitmask>1</collide_bitmask>
              <ode>
                <soft_cfm>0</soft_cfm>
                <soft_erp>0.2</soft_erp>
                <kp>1e+13</kp>
                <kd>1</kd>
                <max_vel>0.01</max_vel>
                <min_depth>0</min_depth>
              </ode>
              <bullet>
                <split_impulse>1</split_impulse>
                <split_impulse_penetration_threshold>-0.01</split_impulse_penetration_threshold>
                <soft_cfm>0</soft_cfm>
                <soft_erp>0.2</soft_erp>
                <kp>1e+13</kp>
                <kd>1</kd>
              </bullet>
            </contact>
          </surface>
        </collision>
      </link>
      <static>0</static>
      <allow_auto_disable>1</allow_auto_disable>
      <pose>0.334419 -0.543897 0 0 -0 0</pose>
    </model>
    <model name='5x5_1000-1_0'>
      <static>1</static>
      <link name='link'>
        <visual name='visual'>
          <geometry>
            <mesh>
              <uri>model://5x5_1000-1/meshes/5x5_1000-1.dae</uri>
              <scale>0.68 0.68 0.68</scale>
            </mesh>
          </geometry>
        </visual>
        <self_collide>0</self_collide>
        <enable_wind>0</enable_wind>
        <kinematic>0</kinematic>
      </link>
      <pose>3.06075 -0.867051 0 0 -0 0</pose>
    </model>
    <model name='5x5_1000-2'>
      <static>1</static>
      <link name='link'>
        <visual name='visual'>
          <geometry>
            <mesh>
              <uri>model://5x5_1000-2/meshes/5x5_1000-2.dae</uri>
              <scale>0.38 0.38 0.38</scale>
            </mesh>
          </geometry>
        </visual>
        <self_collide>0</self_collide>
        <enable_wind>0</enable_wind>
        <kinematic>0</kinematic>
      </link>
      <pose>0.146564 -0.483206 0 0 -0 0</pose>
    </model>
    <model name='Package2'>
      <link name='link_1'>
        <inertial>
          <mass>1</mass>
          <inertia>
            <ixx>0.145833</ixx>
            <ixy>0</ixy>
            <ixz>0</ixz>
            <iyy>0.145833</iyy>
            <iyz>0</iyz>
            <izz>0.125</izz>
          </inertia>
          <pose>0 0 0 0 -0 0</pose>
        </inertial>
        <pose>0 0 0 0 -0 0</pose>
        <gravity>1</gravity>
        <self_collide>0</self_collide>
        <kinematic>0</kinematic>
        <enable_wind>0</enable_wind>
        <visual name='visual'>
          <pose>0 0 0 0 -0 0</pose>
          <geometry>
            <cylinder>
              <radius>0.0762</radius>
              <length>0.0762</length>
            </cylinder>
          </geometry>
          <material>
            <lighting>1</lighting>
            <script>
              <uri>file://media/materials/scripts/gazebo.material</uri>
              <name>Gazebo/Green</name>
            </script>
            <shader type='pixel'>
              <normal_map>__default__</normal_map>
            </shader>
            <ambient>0 0 1 1</ambient>
            <diffuse>0 0 1 1</diffuse>
            <specular>0 0 1 1</specular>
            <emissive>0 0 1 1</emissive>
          </material>
          <transparency>0</transparency>
          <cast_shadows>1</cast_shadows>
        </visual>
        <collision name='collision'>
          <laser_retro>0</laser_retro>
          <max_contacts>10</max_contacts>
          <pose>0 0 0 0 -0 0</pose>
          <geometry>
            <cylinder>
              <radius>0.0762</radius>
              <length>0.0762</length>
            </cylinder>
          </geometry>
          <surface>
            <friction>
              <ode>
                <mu>1</mu>
                <mu2>1</mu2>
                <fdir1>0 0 0</fdir1>
                <slip1>0</slip1>
                <slip2>0</slip2>
              </ode>
              <torsional>
                <coefficient>1</coefficient>
                <patch_radius>0</patch_radius>
                <surface_radius>0</surface_radius>
                <use_patch_radius>1</use_patch_radius>
                <ode>
                  <slip>0</slip>
                </ode>
              </torsional>
            </friction>
            <bounce>
              <restitution_coefficient>0</restitution_coefficient>
              <threshold>1e+06</threshold>
            </bounce>
            <contact>
              <collide_without_contact>0</collide_without_contact>
              <collide_without_contact_bitmask>1</collide_without_contact_bitmask>
              <collide_bitmask>1</collide_bitmask>
              <ode>
                <soft_cfm>0</soft_cfm>
                <soft_erp>0.2</soft_erp>
                <kp>1e+13</kp>
                <kd>1</kd>
                <max_vel>0.01</max_vel>
                <min_depth>0</min_depth>
              </ode>
              <bullet>
                <split_impulse>1</split_impulse>
                <split_impulse_penetration_threshold>-0.01</split_impulse_penetration_threshold>
                <soft_cfm>0</soft_cfm>
                <soft_erp>0.2</soft_erp>
                <kp>1e+13</kp>
                <kd>1</kd>
              </bullet>
            </contact>
          </surface>
        </collision>
      </link>
      <static>0</static>
      <allow_auto_disable>1</allow_auto_disable>
      <pose>-0.144962 -0.800638 0 0 -0 0</pose>
    </model>
    <model name='Dropzone_base'>
      <link name='link_0'>
        <inertial>
          <mass>0.0235743</mass>
          <inertia>
            <ixx>0.00039997</ixx>
            <ixy>0</ixy>
            <ixz>0</ixz>
            <iyy>0.00039086</iyy>
            <iyz>0</iyz>
            <izz>0.00072805</izz>
          </inertia>
          <pose>0 0 0 0 -0 0</pose>
        </inertial>
        <pose>0 0 0 -0 -0 -0.755838</pose>
        <gravity>1</gravity>
        <self_collide>0</self_collide>
        <kinematic>0</kinematic>
        <enable_wind>0</enable_wind>
        <visual name='visual'>
          <pose>0 0 0 0 -0 0</pose>
          <geometry>
            <box>
              <size>0.427763 0.433147 0.01</size>
            </box>
          </geometry>
          <material>
            <lighting>1</lighting>
            <script>
              <uri>file://media/materials/scripts/gazebo.material</uri>
              <name>Gazebo/White</name>
            </script>
            <shader type='pixel'>
              <normal_map>__default__</normal_map>
            </shader>
            <ambient>1 1 1 1</ambient>
            <diffuse>1 1 1 1</diffuse>
            <specular>1 1 1 1</specular>
            <emissive>1 1 1 1</emissive>
          </material>
          <transparency>0</transparency>
          <cast_shadows>1</cast_shadows>
        </visual>
        <collision name='collision'>
          <laser_retro>0</laser_retro>
          <max_contacts>10</max_contacts>
          <pose>0 0 0 0 -0 0</pose>
          <geometry>
            <box>
              <size>0.427763 0.433147 0.01</size>
            </box>
          </geometry>
          <surface>
            <friction>
              <ode>
                <mu>1</mu>
                <mu2>1</mu2>
                <fdir1>0 0 0</fdir1>
                <slip1>0</slip1>
                <slip2>0</slip2>
              </ode>
              <torsional>
                <coefficient>1</coefficient>
                <patch_radius>0</patch_radius>
                <surface_radius>0</surface_radius>
                <use_patch_radius>1</use_patch_radius>
                <ode>
                  <slip>0</slip>
                </ode>
              </torsional>
            </friction>
            <bounce>
              <restitution_coefficient>0</restitution_coefficient>
              <threshold>1e+06</threshold>
            </bounce>
            <contact>
              <collide_without_contact>0</collide_without_contact>
              <collide_without_contact_bitmask>1</collide_without_contact_bitmask>
              <collide_bitmask>1</collide_bitmask>
              <ode>
                <soft_cfm>0</soft_cfm>
                <soft_erp>0.2</soft_erp>
                <kp>1e+13</kp>
                <kd>1</kd>
                <max_vel>0.01</max_vel>
                <min_depth>0</min_depth>
              </ode>
              <bullet>
                <split_impulse>1</split_impulse>
                <split_impulse_penetration_threshold>-0.01</split_impulse_penetration_threshold>
                <soft_cfm>0</soft_cfm>
                <soft_erp>0.2</soft_erp>
                <kp>1e+13</kp>
                <kd>1</kd>
              </bullet>
            </contact>
          </surface>
        </collision>
      </link>
      <static>0</static>
      <allow_auto_disable>1</allow_auto_disable>
      <pose>2.997 -0.94823 0 -0.039608 0 0</pose>
    </model>
    <model name='Dropzone_base_clone'>
      <link name='link_0'>
        <inertial>
          <mass>0.0235743</mass>
          <inertia>
            <ixx>0.00039997</ixx>
            <ixy>0</ixy>
            <ixz>0</ixz>
            <iyy>0.00039086</iyy>
            <iyz>0</iyz>
            <izz>0.00072805</izz>
          </inertia>
          <pose>0 0 0 0 -0 0</pose>
        </inertial>
        <pose>0 0 0 -0 -0 -0.755838</pose>
        <gravity>1</gravity>
        <self_collide>0</self_collide>
        <kinematic>0</kinematic>
        <enable_wind>0</enable_wind>
        <visual name='visual'>
          <pose>0 0 0 0 -0 0</pose>
          <geometry>
            <box>
              <size>0.464269 0.435182 0.01</size>
            </box>
          </geometry>
          <material>
            <lighting>1</lighting>
            <script>
              <uri>file://media/materials/scripts/gazebo.material</uri>
              <name>Gazebo/White</name>
            </script>
            <shader type='pixel'>
              <normal_map>__default__</normal_map>
            </shader>
            <ambient>1 1 1 1</ambient>
            <diffuse>1 1 1 1</diffuse>
            <specular>1 1 1 1</specular>
            <emissive>1 1 1 1</emissive>
          </material>
          <transparency>0</transparency>
          <cast_shadows>1</cast_shadows>
        </visual>
        <collision name='collision'>
          <laser_retro>0</laser_retro>
          <max_contacts>10</max_contacts>
          <pose>0 0 0 0 -0 0</pose>
          <geometry>
            <box>
              <size>0.464269 0.435182 0.01</size>
            </box>
          </geometry>
          <surface>
            <friction>
              <ode>
                <mu>1</mu>
                <mu2>1</mu2>
                <fdir1>0 0 0</fdir1>
                <slip1>0</slip1>
                <slip2>0</slip2>
              </ode>
              <torsional>
                <coefficient>1</coefficient>
                <patch_radius>0</patch_radius>
                <surface_radius>0</surface_radius>
                <use_patch_radius>1</use_patch_radius>
                <ode>
                  <slip>0</slip>
                </ode>
              </torsional>
            </friction>
            <bounce>
              <restitution_coefficient>0</restitution_coefficient>
              <threshold>1e+06</threshold>
            </bounce>
            <contact>
              <collide_without_contact>0</collide_without_contact>
              <collide_without_contact_bitmask>1</collide_without_contact_bitmask>
              <collide_bitmask>1</collide_bitmask>
              <ode>
                <soft_cfm>0</soft_cfm>
                <soft_erp>0.2</soft_erp>
                <kp>1e+13</kp>
                <kd>1</kd>
                <max_vel>0.01</max_vel>
                <min_depth>0</min_depth>
              </ode>
              <bullet>
                <split_impulse>1</split_impulse>
                <split_impulse_penetration_threshold>-0.01</split_impulse_penetration_threshold>
                <soft_cfm>0</soft_cfm>
                <soft_erp>0.2</soft_erp>
                <kp>1e+13</kp>
                <kd>1</kd>
              </bullet>
            </contact>
          </surface>
        </collision>
      </link>
      <static>0</static>
      <allow_auto_disable>1</allow_auto_disable>
      <pose>0.431884 0.662379 0 0 -0 0</pose>
    </model>
    <model name='iris'>
      <frame name='iris_demo::__model__' attached_to='iris_demo::iris::base_link'>
        <pose relative_to='__model__'>0 0 0 0 -0 0</pose>
      </frame>
      <frame name='iris_demo::iris::__model__' attached_to='iris_demo::iris::base_link'>
        <pose relative_to='iris_demo::__model__'>0 0 0.194923 0 -0 0</pose>
      </frame>
      <link name='iris_demo::iris::base_link'>
        <velocity_decay>
          <linear>0</linear>
          <angular>0</angular>
        </velocity_decay>
        <inertial>
          <pose>0 0 0 0 -0 0</pose>
          <mass>1.5</mass>
          <inertia>
            <ixx>0.008</ixx>
            <ixy>0</ixy>
            <ixz>0</ixz>
            <iyy>0.015</iyy>
            <iyz>0</iyz>
            <izz>0.017</izz>
          </inertia>
        </inertial>
        <collision name='base_link_collision'>
          <pose>0 0 -0.08 0 -0 0</pose>
          <geometry>
            <box>
              <size>0.47 0.47 0.23</size>
            </box>
          </geometry>
          <surface>
            <contact>
              <ode>
                <max_vel>100</max_vel>
                <min_depth>0.001</min_depth>
              </ode>
            </contact>
            <friction>
              <ode>
                <mu>100000</mu>
                <mu2>100000</mu2>
              </ode>
              <torsional>
                <ode/>
              </torsional>
            </friction>
            <bounce/>
          </surface>
          <max_contacts>10</max_contacts>
        </collision>
        <visual name='base_link_visual'>
          <geometry>
            <mesh>
              <uri>model://iris_with_standoffs/meshes/iris.dae</uri>
            </mesh>
          </geometry>
          <material>
            <script>
              <name>Gazebo/DarkGrey</name>
              <uri>__default__</uri>
            </script>
          </material>
        </visual>
        <visual name='front_left_leg_visual'>
          <pose>0.123 0.22 -0.11 0 -0 0</pose>
          <geometry>
            <cylinder>
              <radius>0.005</radius>
              <length>0.17</length>
            </cylinder>
          </geometry>
          <material>
            <script>
              <name>Gazebo/FlatBlack</name>
              <uri>file://media/materials/scripts/gazebo.material</uri>
            </script>
          </material>
        </visual>
        <visual name='front_right_leg_visual'>
          <pose>0.123 -0.22 -0.11 0 -0 0</pose>
          <geometry>
            <cylinder>
              <radius>0.005</radius>
              <length>0.17</length>
            </cylinder>
          </geometry>
          <material>
            <script>
              <name>Gazebo/FlatBlack</name>
              <uri>file://media/materials/scripts/gazebo.material</uri>
            </script>
          </material>
        </visual>
        <visual name='rear_left_leg_visual'>
          <pose>-0.14 0.21 -0.11 0 -0 0</pose>
          <geometry>
            <cylinder>
              <radius>0.005</radius>
              <length>0.17</length>
            </cylinder>
          </geometry>
          <material>
            <script>
              <name>Gazebo/FlatBlack</name>
              <uri>file://media/materials/scripts/gazebo.material</uri>
            </script>
          </material>
        </visual>
        <visual name='rear_right_leg_visual'>
          <pose>-0.14 -0.21 -0.11 0 -0 0</pose>
          <geometry>
            <cylinder>
              <radius>0.005</radius>
              <length>0.17</length>
            </cylinder>
          </geometry>
          <material>
            <script>
              <name>Gazebo/FlatBlack</name>
              <uri>file://media/materials/scripts/gazebo.material</uri>
            </script>
          </material>
        </visual>
        <pose relative_to='iris_demo::iris::__model__'>0 0 0 0 -0 0</pose>
        <self_collide>0</self_collide>
        <enable_wind>0</enable_wind>
        <kinematic>0</kinematic>
      </link>
      <link name='iris_demo::iris::iris/ground_truth/odometry_sensorgt_link'>
        <pose relative_to='iris_demo::iris::__model__'>0 0 0 0 -0 0</pose>
        <inertial>
          <pose>0 0 0 0 -0 0</pose>
          <mass>0.15</mass>
          <inertia>
            <ixx>0.0001</ixx>
            <ixy>0</ixy>
            <ixz>0</ixz>
            <iyy>0.0002</iyy>
            <iyz>0</iyz>
            <izz>0.0002</izz>
          </inertia>
        </inertial>
        <self_collide>0</self_collide>
        <enable_wind>0</enable_wind>
        <kinematic>0</kinematic>
      </link>
      <joint name='iris_demo::iris::iris/ground_truth/odometry_sensorgt_joint' type='revolute'>
        <child>iris_demo::iris::iris/ground_truth/odometry_sensorgt_link</child>
        <parent>iris_demo::iris::base_link</parent>
        <axis>
          <xyz expressed_in='iris_demo::iris::__model__'>0 0 1</xyz>
          <limit>
            <lower>0</lower>
            <upper>0</upper>
            <effort>0</effort>
            <velocity>0</velocity>
          </limit>
          <dynamics>
            <damping>1</damping>
            <spring_reference>0</spring_reference>
            <spring_stiffness>0</spring_stiffness>
          </dynamics>
        </axis>
        <physics>
          <ode>
            <implicit_spring_damper>1</implicit_spring_damper>
            <limit>
              <cfm>0</cfm>
              <erp>0.2</erp>
            </limit>
          </ode>
        </physics>
      </joint>
      <link name='iris_demo::iris::iris/imu_link'>
        <inertial>
          <pose>0 0 0 0 -0 0</pose>
          <mass>0.15</mass>
          <inertia>
            <ixx>1e-05</ixx>
            <ixy>0</ixy>
            <ixz>0</ixz>
            <iyy>2e-05</iyy>
            <iyz>0</iyz>
            <izz>2e-05</izz>
          </inertia>
        </inertial>
        <sensor name='imu_sensor' type='imu'>
          <pose>0 0 0 -3.14159 -0 0</pose>
          <always_on>1</always_on>
          <update_rate>1000</update_rate>
          <imu/>
        </sensor>
        <pose relative_to='iris_demo::iris::__model__'>0 0 0 0 -0 0</pose>
        <self_collide>0</self_collide>
        <enable_wind>0</enable_wind>
        <kinematic>0</kinematic>
      </link>
      <joint name='iris_demo::iris::iris/imu_joint' type='revolute'>
        <child>iris_demo::iris::iris/imu_link</child>
        <parent>iris_demo::iris::base_link</parent>
        <axis>
          <xyz expressed_in='iris_demo::iris::__model__'>0 0 1</xyz>
          <limit>
            <lower>0</lower>
            <upper>0</upper>
            <effort>0</effort>
            <velocity>0</velocity>
          </limit>
          <dynamics>
            <damping>1</damping>
            <spring_reference>0</spring_reference>
            <spring_stiffness>0</spring_stiffness>
          </dynamics>
        </axis>
        <physics>
          <ode>
            <implicit_spring_damper>1</implicit_spring_damper>
            <limit>
              <cfm>0</cfm>
              <erp>0.2</erp>
            </limit>
          </ode>
        </physics>
      </joint>
      <link name='iris_demo::iris::rotor_0'>
        <pose relative_to='iris_demo::iris::__model__'>0.13 -0.22 0.023 0 -0 0</pose>
        <inertial>
          <pose>0 0 0 0 -0 0</pose>
          <mass>0.025</mass>
          <inertia>
            <ixx>9.75e-06</ixx>
            <ixy>0</ixy>
            <ixz>0</ixz>
            <iyy>0.000166704</iyy>
            <iyz>0</iyz>
            <izz>0.000167604</izz>
          </inertia>
        </inertial>
        <collision name='rotor_0_collision'>
          <pose>0 0 0 0 -0 0</pose>
          <geometry>
            <cylinder>
              <length>0.005</length>
              <radius>0.1</radius>
            </cylinder>
          </geometry>
          <surface>
            <contact>
              <ode/>
            </contact>
            <friction>
              <ode/>
              <torsional>
                <ode/>
              </torsional>
            </friction>
            <bounce/>
          </surface>
          <max_contacts>10</max_contacts>
        </collision>
        <visual name='rotor_0_visual'>
          <pose>0 0 0 0 -0 0</pose>
          <geometry>
            <mesh>
              <scale>1 1 1</scale>
              <uri>model://iris_with_standoffs/meshes/iris_prop_ccw.dae</uri>
            </mesh>
          </geometry>
          <material>
            <script>
              <name>Gazebo/Blue</name>
              <uri>__default__</uri>
            </script>
          </material>
        </visual>
        <gravity>1</gravity>
        <velocity_decay/>
        <self_collide>0</self_collide>
        <enable_wind>0</enable_wind>
        <kinematic>0</kinematic>
      </link>
      <joint name='iris_demo::iris::rotor_0_joint' type='revolute'>
        <child>iris_demo::iris::rotor_0</child>
        <parent>iris_demo::iris::base_link</parent>
        <axis>
          <xyz expressed_in='iris_demo::iris::__model__'>0 0 1</xyz>
          <limit>
            <lower>-1e+16</lower>
            <upper>1e+16</upper>
          </limit>
          <dynamics>
            <damping>0.004</damping>
            <spring_reference>0</spring_reference>
            <spring_stiffness>0</spring_stiffness>
          </dynamics>
        </axis>
        <physics>
          <ode>
            <implicit_spring_damper>1</implicit_spring_damper>
            <limit>
              <cfm>0</cfm>
              <erp>0.2</erp>
            </limit>
          </ode>
        </physics>
      </joint>
      <link name='iris_demo::iris::rotor_1'>
        <pose relative_to='iris_demo::iris::__model__'>-0.13 0.2 0.023 0 -0 0</pose>
        <inertial>
          <pose>0 0 0 0 -0 0</pose>
          <mass>0.025</mass>
          <inertia>
            <ixx>9.75e-06</ixx>
            <ixy>0</ixy>
            <ixz>0</ixz>
            <iyy>0.000166704</iyy>
            <iyz>0</iyz>
            <izz>0.000167604</izz>
          </inertia>
        </inertial>
        <collision name='rotor_1_collision'>
          <pose>0 0 0 0 -0 0</pose>
          <geometry>
            <cylinder>
              <length>0.005</length>
              <radius>0.1</radius>
            </cylinder>
          </geometry>
          <surface>
            <contact>
              <ode/>
            </contact>
            <friction>
              <ode/>
              <torsional>
                <ode/>
              </torsional>
            </friction>
            <bounce/>
          </surface>
          <max_contacts>10</max_contacts>
        </collision>
        <visual name='rotor_1_visual'>
          <pose>0 0 0 0 -0 0</pose>
          <geometry>
            <mesh>
              <scale>1 1 1</scale>
              <uri>model://iris_with_standoffs/meshes/iris_prop_ccw.dae</uri>
            </mesh>
          </geometry>
          <material>
            <script>
              <name>Gazebo/DarkGrey</name>
              <uri>__default__</uri>
            </script>
          </material>
        </visual>
        <gravity>1</gravity>
        <velocity_decay/>
        <self_collide>0</self_collide>
        <enable_wind>0</enable_wind>
        <kinematic>0</kinematic>
      </link>
      <joint name='iris_demo::iris::rotor_1_joint' type='revolute'>
        <child>iris_demo::iris::rotor_1</child>
        <parent>iris_demo::iris::base_link</parent>
        <axis>
          <xyz expressed_in='iris_demo::iris::__model__'>0 0 1</xyz>
          <limit>
            <lower>-1e+16</lower>
            <upper>1e+16</upper>
          </limit>
          <dynamics>
            <damping>0.004</damping>
            <spring_reference>0</spring_reference>
            <spring_stiffness>0</spring_stiffness>
          </dynamics>
        </axis>
        <physics>
          <ode>
            <implicit_spring_damper>1</implicit_spring_damper>
            <limit>
              <cfm>0</cfm>
              <erp>0.2</erp>
            </limit>
          </ode>
        </physics>
      </joint>
      <link name='iris_demo::iris::rotor_2'>
        <pose relative_to='iris_demo::iris::__model__'>0.13 0.22 0.023 0 -0 0</pose>
        <inertial>
          <pose>0 0 0 0 -0 0</pose>
          <mass>0.025</mass>
          <inertia>
            <ixx>9.75e-06</ixx>
            <ixy>0</ixy>
            <ixz>0</ixz>
            <iyy>0.000166704</iyy>
            <iyz>0</iyz>
            <izz>0.000167604</izz>
          </inertia>
        </inertial>
        <collision name='rotor_2_collision'>
          <pose>0 0 0 0 -0 0</pose>
          <geometry>
            <cylinder>
              <length>0.005</length>
              <radius>0.1</radius>
            </cylinder>
          </geometry>
          <surface>
            <contact>
              <ode/>
            </contact>
            <friction>
              <ode/>
              <torsional>
                <ode/>
              </torsional>
            </friction>
            <bounce/>
          </surface>
          <max_contacts>10</max_contacts>
        </collision>
        <visual name='rotor_2_visual'>
          <pose>0 0 0 0 -0 0</pose>
          <geometry>
            <mesh>
              <scale>1 1 1</scale>
              <uri>model://iris_with_standoffs/meshes/iris_prop_cw.dae</uri>
            </mesh>
          </geometry>
          <material>
            <script>
              <name>Gazebo/Blue</name>
              <uri>__default__</uri>
            </script>
          </material>
        </visual>
        <gravity>1</gravity>
        <velocity_decay/>
        <self_collide>0</self_collide>
        <enable_wind>0</enable_wind>
        <kinematic>0</kinematic>
      </link>
      <joint name='iris_demo::iris::rotor_2_joint' type='revolute'>
        <child>iris_demo::iris::rotor_2</child>
        <parent>iris_demo::iris::base_link</parent>
        <axis>
          <xyz expressed_in='iris_demo::iris::__model__'>0 0 1</xyz>
          <limit>
            <lower>-1e+16</lower>
            <upper>1e+16</upper>
          </limit>
          <dynamics>
            <damping>0.004</damping>
            <spring_reference>0</spring_reference>
            <spring_stiffness>0</spring_stiffness>
          </dynamics>
        </axis>
        <physics>
          <ode>
            <implicit_spring_damper>1</implicit_spring_damper>
            <limit>
              <cfm>0</cfm>
              <erp>0.2</erp>
            </limit>
          </ode>
        </physics>
      </joint>
      <link name='iris_demo::iris::rotor_3'>
        <pose relative_to='iris_demo::iris::__model__'>-0.13 -0.2 0.023 0 -0 0</pose>
        <inertial>
          <pose>0 0 0 0 -0 0</pose>
          <mass>0.025</mass>
          <inertia>
            <ixx>9.75e-06</ixx>
            <ixy>0</ixy>
            <ixz>0</ixz>
            <iyy>0.000166704</iyy>
            <iyz>0</iyz>
            <izz>0.000167604</izz>
          </inertia>
        </inertial>
        <collision name='rotor_3_collision'>
          <pose>0 0 0 0 -0 0</pose>
          <geometry>
            <cylinder>
              <length>0.005</length>
              <radius>0.1</radius>
            </cylinder>
          </geometry>
          <surface>
            <contact>
              <ode/>
            </contact>
            <friction>
              <ode/>
              <torsional>
                <ode/>
              </torsional>
            </friction>
            <bounce/>
          </surface>
          <max_contacts>10</max_contacts>
        </collision>
        <visual name='rotor_3_visual'>
          <pose>0 0 0 0 -0 0</pose>
          <geometry>
            <mesh>
              <scale>1 1 1</scale>
              <uri>model://iris_with_standoffs/meshes/iris_prop_cw.dae</uri>
            </mesh>
          </geometry>
          <material>
            <script>
              <name>Gazebo/DarkGrey</name>
              <uri>__default__</uri>
            </script>
          </material>
        </visual>
        <gravity>1</gravity>
        <velocity_decay/>
        <self_collide>0</self_collide>
        <enable_wind>0</enable_wind>
        <kinematic>0</kinematic>
      </link>
      <joint name='iris_demo::iris::rotor_3_joint' type='revolute'>
        <child>iris_demo::iris::rotor_3</child>
        <parent>iris_demo::iris::base_link</parent>
        <axis>
          <xyz expressed_in='iris_demo::iris::__model__'>0 0 1</xyz>
          <limit>
            <lower>-1e+16</lower>
            <upper>1e+16</upper>
          </limit>
          <dynamics>
            <damping>0.004</damping>
            <spring_reference>0</spring_reference>
            <spring_stiffness>0</spring_stiffness>
          </dynamics>
        </axis>
        <physics>
          <ode>
            <implicit_spring_damper>1</implicit_spring_damper>
            <limit>
              <cfm>0</cfm>
              <erp>0.2</erp>
            </limit>
          </ode>
        </physics>
      </joint>
      <static>0</static>
      <frame name='iris_demo::gimbal_small_2d::__model__' attached_to='iris_demo::gimbal_small_2d::base_link'>
        <pose relative_to='iris_demo::__model__'>0 -0.01 0.07 1.57 -0 1.57</pose>
      </frame>
      <link name='iris_demo::gimbal_small_2d::base_link'>
        <inertial>
          <mass>0.2</mass>
          <inertia>
            <ixx>0.0001</ixx>
            <ixy>0</ixy>
            <ixz>0</ixz>
            <iyy>0.0001</iyy>
            <iyz>0</iyz>
            <izz>0.0001</izz>
          </inertia>
          <pose>0 0 0 0 -0 0</pose>
        </inertial>
        <visual name='base_main_viz'>
          <geometry>
            <mesh>
              <scale>0.001 0.001 0.001</scale>
              <uri>model://gimbal_small_2d/meshes/base_main.dae</uri>
            </mesh>
          </geometry>
          <material>
            <script>
              <uri>file://media/materials/scripts/gazebo.material</uri>
              <name>Gazebo/FlatBlack</name>
            </script>
          </material>
        </visual>
        <visual name='base_arm_viz'>
          <geometry>
            <mesh>
              <scale>0.001 0.001 0.001</scale>
              <uri>model://gimbal_small_2d/meshes/base_arm.dae</uri>
            </mesh>
          </geometry>
          <material>
            <script>
              <uri>file://media/materials/scripts/gazebo.material</uri>
              <name>Gazebo/FlatBlack</name>
            </script>
          </material>
        </visual>
        <collision name='base_col'>
          <pose>0.01 0.075 -0.025 0 -0 0</pose>
          <geometry>
            <box>
              <size>0.1 0.05 0.15</size>
            </box>
          </geometry>
          <surface>
            <friction>
              <ode>
                <mu>1</mu>
                <mu2>1</mu2>
                <fdir1>0 0 0</fdir1>
                <slip1>0</slip1>
                <slip2>0</slip2>
              </ode>
              <torsional>
                <ode/>
              </torsional>
            </friction>
            <contact>
              <ode/>
            </contact>
            <bounce/>
          </surface>
          <max_contacts>10</max_contacts>
        </collision>
        <pose relative_to='iris_demo::gimbal_small_2d::__model__'>0 0 0 0 -0 0</pose>
        <self_collide>0</self_collide>
        <enable_wind>0</enable_wind>
        <kinematic>0</kinematic>
      </link>
      <link name='iris_demo::gimbal_small_2d::tilt_link'>
        <inertial>
          <mass>0.01</mass>
          <inertia>
            <ixx>1e-05</ixx>
            <ixy>0</ixy>
            <ixz>0</ixz>
            <iyy>1e-05</iyy>
            <iyz>0</iyz>
            <izz>1e-05</izz>
          </inertia>
          <pose>0 0 0 0 -0 0</pose>
        </inertial>
        <visual name='tilt_viz'>
          <pose>0 0 -0.005 0 -0 0</pose>
          <geometry>
            <mesh>
              <scale>0.001 0.001 0.001</scale>
              <uri>model://gimbal_small_2d/meshes/tilt.dae</uri>
            </mesh>
          </geometry>
          <material>
            <script>
              <uri>file://media/materials/scripts/gazebo.material</uri>
              <name>Gazebo/Grey</name>
            </script>
          </material>
        </visual>
        <collision name='tilt_col'>
          <pose>0 0 -0.005 0 -0 0</pose>
          <geometry>
            <mesh>
              <scale>0.001 0.001 0.001</scale>
              <uri>model://gimbal_small_2d/meshes/tilt.dae</uri>
            </mesh>
          </geometry>
          <max_contacts>10</max_contacts>
          <surface>
            <contact>
              <ode/>
            </contact>
            <bounce/>
            <friction>
              <torsional>
                <ode/>
              </torsional>
              <ode/>
            </friction>
          </surface>
        </collision>
        <visual name='camera_viz'>
          <pose>0 0 0.02 0 -0 0</pose>
          <geometry>
            <cylinder>
              <radius>0.025</radius>
              <length>0.05</length>
            </cylinder>
          </geometry>
          <material>
            <script>
              <uri>file://media/materials/scripts/gazebo.material</uri>
              <name>Gazebo/Grey</name>
            </script>
          </material>
        </visual>
        <collision name='camera_col'>
          <pose>0 0 0.02 0 -0 0</pose>
          <geometry>
            <cylinder>
              <radius>0.025</radius>
              <length>0.05</length>
            </cylinder>
          </geometry>
          <max_contacts>10</max_contacts>
          <surface>
            <contact>
              <ode/>
            </contact>
            <bounce/>
            <friction>
              <torsional>
                <ode/>
              </torsional>
              <ode/>
            </friction>
          </surface>
        </collision>
        <sensor name='camera' type='camera'>
          <pose>0 0 0 -1.57 -1.57 0</pose>
          <camera>
            <horizontal_fov>2</horizontal_fov>
            <image>
              <width>640</width>
              <height>480</height>
            </image>
            <clip>
              <near>0.05</near>
              <far>15000</far>
            </clip>
          </camera>
          <always_on>1</always_on>
          <update_rate>10</update_rate>
          <visualize>1</visualize>
        </sensor>
        <pose relative_to='iris_demo::gimbal_small_2d::__model__'>0 0 0 0 -0 0</pose>
        <self_collide>0</self_collide>
        <enable_wind>0</enable_wind>
        <kinematic>0</kinematic>
      </link>
      <joint name='iris_demo::gimbal_small_2d::tilt_joint' type='revolute'>
        <parent>iris_demo::gimbal_small_2d::base_link</parent>
        <child>iris_demo::gimbal_small_2d::tilt_link</child>
        <physics>
          <ode>
            <implicit_spring_damper>1</implicit_spring_damper>
            <limit>
              <cfm>0</cfm>
              <erp>0.2</erp>
            </limit>
          </ode>
        </physics>
        <axis>
          <xyz expressed_in='iris_demo::gimbal_small_2d::__model__'>1 0 0</xyz>
          <dynamics>
            <damping>0.5</damping>
            <spring_reference>0</spring_reference>
            <spring_stiffness>0</spring_stiffness>
          </dynamics>
          <limit>
            <lower>-0.1</lower>
            <upper>3.14159</upper>
            <effort>10</effort>
            <velocity>-1</velocity>
          </limit>
        </axis>
        <pose>0 0 0.02 0 -0 0</pose>
      </joint>
      <plugin name='gimbal_small_2d' filename='libGimbalSmall2dPlugin.so'>
        <joint>iris_demo::gimbal_small_2d::tilt_joint</joint>
      </plugin>
      <joint name='iris_demo::iris_gimbal_mount' type='revolute'>
        <parent>iris_demo::iris::base_link</parent>
        <child>iris_demo::gimbal_small_2d::base_link</child>
        <axis>
          <limit>
            <lower>0</lower>
            <upper>0</upper>
          </limit>
          <xyz expressed_in='iris_demo::__model__'>0 0 1</xyz>
          <dynamics>
            <spring_reference>0</spring_reference>
            <spring_stiffness>0</spring_stiffness>
          </dynamics>
        </axis>
      </joint>
      <plugin name='rotor_0_blade_1' filename='libLiftDragPlugin.so'>
        <a0>0.1</a0>
        <alpha_stall>1.4</alpha_stall>
        <cla>0.2500</cla>
        <cda>0.10</cda>
        <cma>0.00</cma>
        <cla_stall>-0.025</cla_stall>
        <cda_stall>0.0</cda_stall>
        <cma_stall>0.0</cma_stall>
        <area>0.2</area>
        <air_density>1.2041</air_density>
        <cp>0.084 0 0</cp>
        <forward>0 1 0</forward>
        <upward>0 0 1</upward>
        <link_name>iris_demo::iris::rotor_0</link_name>
      </plugin>
      <plugin name='rotor_0_blade_2' filename='libLiftDragPlugin.so'>
        <a0>0.1</a0>
        <alpha_stall>1.4</alpha_stall>
        <cla>0.2500</cla>
        <cda>0.10</cda>
        <cma>0.00</cma>
        <cla_stall>-0.025</cla_stall>
        <cda_stall>0.0</cda_stall>
        <cma_stall>0.0</cma_stall>
        <area>0.2</area>
        <air_density>1.2041</air_density>
        <cp>-0.084 0 0</cp>
        <forward>0 -1 0</forward>
        <upward>0 0 1</upward>
        <link_name>iris_demo::iris::rotor_0</link_name>
      </plugin>
      <plugin name='rotor_1_blade_1' filename='libLiftDragPlugin.so'>
        <a0>0.1</a0>
        <alpha_stall>1.4</alpha_stall>
        <cla>0.2500</cla>
        <cda>0.10</cda>
        <cma>0.00</cma>
        <cla_stall>-0.025</cla_stall>
        <cda_stall>0.0</cda_stall>
        <cma_stall>0.0</cma_stall>
        <area>0.2</area>
        <air_density>1.2041</air_density>
        <cp>0.084 0 0</cp>
        <forward>0 1 0</forward>
        <upward>0 0 1</upward>
        <link_name>iris_demo::iris::rotor_1</link_name>
      </plugin>
      <plugin name='rotor_1_blade_2' filename='libLiftDragPlugin.so'>
        <a0>0.1</a0>
        <alpha_stall>1.4</alpha_stall>
        <cla>0.2500</cla>
        <cda>0.10</cda>
        <cma>0.00</cma>
        <cla_stall>-0.025</cla_stall>
        <cda_stall>0.0</cda_stall>
        <cma_stall>0.0</cma_stall>
        <area>0.2</area>
        <air_density>1.2041</air_density>
        <cp>-0.084 0 0</cp>
        <forward>0 -1 0</forward>
        <upward>0 0 1</upward>
        <link_name>iris_demo::iris::rotor_1</link_name>
      </plugin>
      <plugin name='rotor_2_blade_1' filename='libLiftDragPlugin.so'>
        <a0>0.1</a0>
        <alpha_stall>1.4</alpha_stall>
        <cla>0.2500</cla>
        <cda>0.10</cda>
        <cma>0.00</cma>
        <cla_stall>-0.025</cla_stall>
        <cda_stall>0.0</cda_stall>
        <cma_stall>0.0</cma_stall>
        <area>0.2</area>
        <air_density>1.2041</air_density>
        <cp>0.084 0 0</cp>
        <forward>0 -1 0</forward>
        <upward>0 0 1</upward>
        <link_name>iris_demo::iris::rotor_2</link_name>
      </plugin>
      <plugin name='rotor_2_blade_2' filename='libLiftDragPlugin.so'>
        <a0>0.1</a0>
        <alpha_stall>1.4</alpha_stall>
        <cla>0.2500</cla>
        <cda>0.10</cda>
        <cma>0.00</cma>
        <cla_stall>-0.025</cla_stall>
        <cda_stall>0.0</cda_stall>
        <cma_stall>0.0</cma_stall>
        <area>0.2</area>
        <air_density>1.2041</air_density>
        <cp>-0.084 0 0</cp>
        <forward>0 1 0</forward>
        <upward>0 0 1</upward>
        <link_name>iris_demo::iris::rotor_2</link_name>
      </plugin>
      <plugin name='rotor_3_blade_1' filename='libLiftDragPlugin.so'>
        <a0>0.1</a0>
        <alpha_stall>1.4</alpha_stall>
        <cla>0.2500</cla>
        <cda>0.10</cda>
        <cma>0.00</cma>
        <cla_stall>-0.025</cla_stall>
        <cda_stall>0.0</cda_stall>
        <cma_stall>0.0</cma_stall>
        <area>0.2</area>
        <air_density>1.2041</air_density>
        <cp>0.084 0 0</cp>
        <forward>0 -1 0</forward>
        <upward>0 0 1</upward>
        <link_name>iris_demo::iris::rotor_3</link_name>
      </plugin>
      <plugin name='rotor_3_blade_2' filename='libLiftDragPlugin.so'>
        <a0>0.1</a0>
        <alpha_stall>1.4</alpha_stall>
        <cla>0.2500</cla>
        <cda>0.10</cda>
        <cma>0.00</cma>
        <cla_stall>-0.025</cla_stall>
        <cda_stall>0.0</cda_stall>
        <cma_stall>0.0</cma_stall>
        <area>0.2</area>
        <air_density>1.2041</air_density>
        <cp>-0.084 0 0</cp>
        <forward>0 1 0</forward>
        <upward>0 0 1</upward>
        <link_name>iris_demo::iris::rotor_3</link_name>
      </plugin>
      <plugin name='arducopter_plugin' filename='libArduCopterPlugin.so'>
        <imuName>iris_demo::iris::iris/imu_link::imu_sensor</imuName>
        <connectionTimeoutMaxCount>5</connectionTimeoutMaxCount>
        <rotor id='0'>
          <vel_p_gain>0.01</vel_p_gain>
          <vel_i_gain>0</vel_i_gain>
          <vel_d_gain>0</vel_d_gain>
          <vel_i_max>0</vel_i_max>
          <vel_i_min>0</vel_i_min>
          <vel_cmd_max>2.0</vel_cmd_max>
          <vel_cmd_min>-2.0</vel_cmd_min>
          <jointName>iris_demo::iris::rotor_0_joint</jointName>
          <turningDirection>ccw</turningDirection>
          <rotorVelocitySlowdownSim>1</rotorVelocitySlowdownSim>
        </rotor>
        <rotor id='1'>
          <vel_p_gain>0.01</vel_p_gain>
          <vel_i_gain>0</vel_i_gain>
          <vel_d_gain>0</vel_d_gain>
          <vel_i_max>0</vel_i_max>
          <vel_i_min>0</vel_i_min>
          <vel_cmd_max>2.0</vel_cmd_max>
          <vel_cmd_min>-2.0</vel_cmd_min>
          <jointName>iris_demo::iris::rotor_1_joint</jointName>
          <turningDirection>ccw</turningDirection>
          <rotorVelocitySlowdownSim>1</rotorVelocitySlowdownSim>
        </rotor>
        <rotor id='2'>
          <vel_p_gain>0.01</vel_p_gain>
          <vel_i_gain>0</vel_i_gain>
          <vel_d_gain>0</vel_d_gain>
          <vel_i_max>0</vel_i_max>
          <vel_i_min>0</vel_i_min>
          <vel_cmd_max>2.0</vel_cmd_max>
          <vel_cmd_min>-2.0</vel_cmd_min>
          <jointName>iris_demo::iris::rotor_2_joint</jointName>
          <turningDirection>cw</turningDirection>
          <rotorVelocitySlowdownSim>1</rotorVelocitySlowdownSim>
        </rotor>
        <rotor id='3'>
          <vel_p_gain>0.01</vel_p_gain>
          <vel_i_gain>0</vel_i_gain>
          <vel_d_gain>0</vel_d_gain>
          <vel_i_max>0</vel_i_max>
          <vel_i_min>0</vel_i_min>
          <vel_cmd_max>2.0</vel_cmd_max>
          <vel_cmd_min>-2.0</vel_cmd_min>
          <jointName>iris_demo::iris::rotor_3_joint</jointName>
          <turningDirection>cw</turningDirection>
          <rotorVelocitySlowdownSim>1</rotorVelocitySlowdownSim>
        </rotor>
      </plugin>
      <link name='camera'>
        <pose>0 -0.01 0.07 1.57 -0 1.57</pose>
        <inertial>
          <pose>0 0 0 0 -0 0</pose>
          <mass>0.1</mass>
          <inertia>
            <ixx>0.001</ixx>
            <ixy>0</ixy>
            <ixz>0</ixz>
            <iyy>0.001</iyy>
            <iyz>0</iyz>
            <izz>0.001</izz>
          </inertia>
        </inertial>
        <visual name='visual'>
          <pose>0 0 0 0 -0 0</pose>
          <geometry>
            <cylinder>
              <radius>0.025</radius>
              <length>0.025</length>
            </cylinder>
          </geometry>
          <material>
            <script>
              <uri>file://media/materials/scripts/gazebo.material</uri>
              <name>Gazebo/Grey</name>
            </script>
          </material>
        </visual>
        <sensor name='camera' type='camera'>
          <pose>0 0 0 -1.57 -1.57 0</pose>
          <camera>
            <horizontal_fov>1.0472</horizontal_fov>
            <image>
              <width>640</width>
              <height>480</height>
            </image>
            <clip>
              <near>0.05</near>
              <far>1000</far>
            </clip>
          </camera>
          <always_on>1</always_on>
          <update_rate>10</update_rate>
          <visualize>1</visualize>
          <plugin name='camera_controller' filename='libgazebo_ros_camera.so'>
            <alwaysOn>1</alwaysOn>
            <updateRate>0.0</updateRate>
            <cameraName>webcam</cameraName>
            <imageTopicName>image_raw</imageTopicName>
            <cameraInfoTopicName>camera_info</cameraInfoTopicName>
            <frameName>camera_link</frameName>
            <hackBaseline>0.07</hackBaseline>
            <distortionK1>0.0</distortionK1>
            <distortionK2>0.0</distortionK2>
            <distortionK3>0.0</distortionK3>
            <distortionT1>0.0</distortionT1>
            <distortionT2>0.0</distortionT2>
          </plugin>
        </sensor>
        <self_collide>0</self_collide>
        <enable_wind>0</enable_wind>
        <kinematic>0</kinematic>
      </link>
      <joint name='base_camera_joint' type='revolute'>
        <pose>0 0 0 0 -0 0</pose>
        <parent>iris::iris_demo::gimbal_small_2d::tilt_link</parent>
        <child>camera</child>
        <axis>
          <limit>
            <lower>0</lower>
            <upper>0</upper>
          </limit>
          <xyz>0 0 1</xyz>
          <dynamics>
            <spring_reference>0</spring_reference>
            <spring_stiffness>0</spring_stiffness>
          </dynamics>
          <use_parent_model_frame>1</use_parent_model_frame>
        </axis>
      </joint>
    </model>
    <model name='Drop_zone'>
      <link name='Wall_0'>
        <pose>0.20446 -0.023502 0 0 -0 0.784218</pose>
        <self_collide>0</self_collide>
        <enable_wind>0</enable_wind>
        <kinematic>0</kinematic>
        <gravity>1</gravity>
        <inertial>
          <mass>1</mass>
          <pose>0 0 0 0 -0 0</pose>
          <inertia>
            <ixx>1</ixx>
            <ixy>0</ixy>
            <ixz>0</ixz>
            <iyy>1</iyy>
            <iyz>0</iyz>
            <izz>1</izz>
          </inertia>
        </inertial>
        <visual name='Wall_0_Visual'>
          <pose>0 0 0.0125 0 -0 0</pose>
          <geometry>
            <box>
              <size>0.74892 0.15 0.025</size>
            </box>
          </geometry>
          <material>
            <script>
              <uri>file://media/materials/scripts/gazebo.material</uri>
              <name>Gazebo/Grey</name>
            </script>
            <ambient>1 0 0 1</ambient>
            <shader type='pixel'>
              <normal_map>__default__</normal_map>
            </shader>
            <diffuse>1 0 0 1</diffuse>
            <specular>1 0 0 1</specular>
            <emissive>1 0 0 1</emissive>
          </material>
          <meta>
            <layer>0</layer>
          </meta>
          <transparency>0</transparency>
          <cast_shadows>1</cast_shadows>
        </visual>
        <collision name='Wall_0_Collision'>
          <laser_retro>0</laser_retro>
          <max_contacts>10</max_contacts>
          <pose>0 0 0.0125 0 -0 0</pose>
          <geometry>
            <box>
              <size>0.74892 0.15 0.025</size>
            </box>
          </geometry>
          <surface>
            <friction>
              <ode>
                <mu>1</mu>
                <mu2>1</mu2>
                <fdir1>0 0 0</fdir1>
                <slip1>0</slip1>
                <slip2>0</slip2>
              </ode>
              <torsional>
                <coefficient>1</coefficient>
                <patch_radius>0</patch_radius>
                <surface_radius>0</surface_radius>
                <use_patch_radius>1</use_patch_radius>
                <ode>
                  <slip>0</slip>
                </ode>
              </torsional>
            </friction>
            <bounce>
              <restitution_coefficient>0</restitution_coefficient>
              <threshold>1e+06</threshold>
            </bounce>
            <contact>
              <collide_without_contact>0</collide_without_contact>
              <collide_without_contact_bitmask>1</collide_without_contact_bitmask>
              <collide_bitmask>1</collide_bitmask>
              <ode>
                <soft_cfm>0</soft_cfm>
                <soft_erp>0.2</soft_erp>
                <kp>1e+13</kp>
                <kd>1</kd>
                <max_vel>0.01</max_vel>
                <min_depth>0</min_depth>
              </ode>
              <bullet>
                <split_impulse>1</split_impulse>
                <split_impulse_penetration_threshold>-0.01</split_impulse_penetration_threshold>
                <soft_cfm>0</soft_cfm>
                <soft_erp>0.2</soft_erp>
                <kp>1e+13</kp>
                <kd>1</kd>
              </bullet>
            </contact>
          </surface>
        </collision>
      </link>
      <link name='Wall_1'>
        <pose>0.63646 -0.020502 0 0 0 -0.758567</pose>
        <self_collide>0</self_collide>
        <enable_wind>0</enable_wind>
        <kinematic>0</kinematic>
        <gravity>1</gravity>
        <inertial>
          <mass>1</mass>
          <pose>0 0 0 0 -0 0</pose>
          <inertia>
            <ixx>1</ixx>
            <ixy>0</ixy>
            <ixz>0</ixz>
            <iyy>1</iyy>
            <iyz>0</iyz>
            <izz>1</izz>
          </inertia>
        </inertial>
        <visual name='Wall_1_Visual'>
          <pose>0 0 0.0125 0 -0 0</pose>
          <geometry>
            <box>
              <size>0.756355 0.15 0.025</size>
            </box>
          </geometry>
          <material>
            <script>
              <uri>file://media/materials/scripts/gazebo.material</uri>
              <name>Gazebo/Grey</name>
            </script>
            <ambient>1 0 0 1</ambient>
            <shader type='pixel'>
              <normal_map>__default__</normal_map>
            </shader>
            <diffuse>1 0 0 1</diffuse>
            <specular>1 0 0 1</specular>
            <emissive>1 0 0 1</emissive>
          </material>
          <meta>
            <layer>0</layer>
          </meta>
          <transparency>0</transparency>
          <cast_shadows>1</cast_shadows>
        </visual>
        <collision name='Wall_1_Collision'>
          <laser_retro>0</laser_retro>
          <max_contacts>10</max_contacts>
          <pose>0 0 0.0125 0 -0 0</pose>
          <geometry>
            <box>
              <size>0.756355 0.15 0.025</size>
            </box>
          </geometry>
          <surface>
            <friction>
              <ode>
                <mu>1</mu>
                <mu2>1</mu2>
                <fdir1>0 0 0</fdir1>
                <slip1>0</slip1>
                <slip2>0</slip2>
              </ode>
              <torsional>
                <coefficient>1</coefficient>
                <patch_radius>0</patch_radius>
                <surface_radius>0</surface_radius>
                <use_patch_radius>1</use_patch_radius>
                <ode>
                  <slip>0</slip>
                </ode>
              </torsional>
            </friction>
            <bounce>
              <restitution_coefficient>0</restitution_coefficient>
              <threshold>1e+06</threshold>
            </bounce>
            <contact>
              <collide_without_contact>0</collide_without_contact>
              <collide_without_contact_bitmask>1</collide_without_contact_bitmask>
              <collide_bitmask>1</collide_bitmask>
              <ode>
                <soft_cfm>0</soft_cfm>
                <soft_erp>0.2</soft_erp>
                <kp>1e+13</kp>
                <kd>1</kd>
                <max_vel>0.01</max_vel>
                <min_depth>0</min_depth>
              </ode>
              <bullet>
                <split_impulse>1</split_impulse>
                <split_impulse_penetration_threshold>-0.01</split_impulse_penetration_threshold>
                <soft_cfm>0</soft_cfm>
                <soft_erp>0.2</soft_erp>
                <kp>1e+13</kp>
                <kd>1</kd>
              </bullet>
            </contact>
          </surface>
        </collision>
      </link>
      <link name='Wall_2'>
        <pose>0.65046 -0.438002 0 0 0 -2.34897</pose>
        <self_collide>0</self_collide>
        <enable_wind>0</enable_wind>
        <kinematic>0</kinematic>
        <gravity>1</gravity>
        <inertial>
          <mass>1</mass>
          <pose>0 0 0 0 -0 0</pose>
          <inertia>
            <ixx>1</ixx>
            <ixy>0</ixy>
            <ixz>0</ixz>
            <iyy>1</iyy>
            <iyz>0</iyz>
            <izz>1</izz>
          </inertia>
        </inertial>
        <visual name='Wall_2_Visual'>
          <pose>0 0 0.0125 0 -0 0</pose>
          <geometry>
            <box>
              <size>0.736724 0.15 0.025</size>
            </box>
          </geometry>
          <material>
            <script>
              <uri>file://media/materials/scripts/gazebo.material</uri>
              <name>Gazebo/Grey</name>
            </script>
            <ambient>1 0 0 1</ambient>
            <shader type='pixel'>
              <normal_map>__default__</normal_map>
            </shader>
            <diffuse>1 0 0 1</diffuse>
            <specular>1 0 0 1</specular>
            <emissive>1 0 0 1</emissive>
          </material>
          <meta>
            <layer>0</layer>
          </meta>
          <transparency>0</transparency>
          <cast_shadows>1</cast_shadows>
        </visual>
        <collision name='Wall_2_Collision'>
          <laser_retro>0</laser_retro>
          <max_contacts>10</max_contacts>
          <pose>0 0 0.0125 0 -0 0</pose>
          <geometry>
            <box>
              <size>0.736724 0.15 0.025</size>
            </box>
          </geometry>
          <surface>
            <friction>
              <ode>
                <mu>1</mu>
                <mu2>1</mu2>
                <fdir1>0 0 0</fdir1>
                <slip1>0</slip1>
                <slip2>0</slip2>
              </ode>
              <torsional>
                <coefficient>1</coefficient>
                <patch_radius>0</patch_radius>
                <surface_radius>0</surface_radius>
                <use_patch_radius>1</use_patch_radius>
                <ode>
                  <slip>0</slip>
                </ode>
              </torsional>
            </friction>
            <bounce>
              <restitution_coefficient>0</restitution_coefficient>
              <threshold>1e+06</threshold>
            </bounce>
            <contact>
              <collide_without_contact>0</collide_without_contact>
              <collide_without_contact_bitmask>1</collide_without_contact_bitmask>
              <collide_bitmask>1</collide_bitmask>
              <ode>
                <soft_cfm>0</soft_cfm>
                <soft_erp>0.2</soft_erp>
                <kp>1e+13</kp>
                <kd>1</kd>
                <max_vel>0.01</max_vel>
                <min_depth>0</min_depth>
              </ode>
              <bullet>
                <split_impulse>1</split_impulse>
                <split_impulse_penetration_threshold>-0.01</split_impulse_penetration_threshold>
                <soft_cfm>0</soft_cfm>
                <soft_erp>0.2</soft_erp>
                <kp>1e+13</kp>
                <kd>1</kd>
              </bullet>
            </contact>
          </surface>
        </collision>
      </link>
      <link name='Wall_3'>
        <pose>0.22146 -0.438002 0 0 -0 2.38859</pose>
        <self_collide>0</self_collide>
        <enable_wind>0</enable_wind>
        <kinematic>0</kinematic>
        <gravity>1</gravity>
        <inertial>
          <mass>1</mass>
          <pose>0 0 0 0 -0 0</pose>
          <inertia>
            <ixx>1</ixx>
            <ixy>0</ixy>
            <ixz>0</ixz>
            <iyy>1</iyy>
            <iyz>0</iyz>
            <izz>1</izz>
          </inertia>
        </inertial>
        <visual name='Wall_3_Visual'>
          <pose>0 0 0.0125 0 -0 0</pose>
          <geometry>
            <box>
              <size>0.760813 0.15 0.025</size>
            </box>
          </geometry>
          <material>
            <script>
              <uri>file://media/materials/scripts/gazebo.material</uri>
              <name>Gazebo/Grey</name>
            </script>
            <ambient>1 0 0 1</ambient>
            <shader type='pixel'>
              <normal_map>__default__</normal_map>
            </shader>
            <diffuse>1 0 0 1</diffuse>
            <specular>1 0 0 1</specular>
            <emissive>1 0 0 1</emissive>
          </material>
          <meta>
            <layer>0</layer>
          </meta>
          <transparency>0</transparency>
          <cast_shadows>1</cast_shadows>
        </visual>
        <collision name='Wall_3_Collision'>
          <laser_retro>0</laser_retro>
          <max_contacts>10</max_contacts>
          <pose>0 0 0.0125 0 -0 0</pose>
          <geometry>
            <box>
              <size>0.760813 0.15 0.025</size>
            </box>
          </geometry>
          <surface>
            <friction>
              <ode>
                <mu>1</mu>
                <mu2>1</mu2>
                <fdir1>0 0 0</fdir1>
                <slip1>0</slip1>
                <slip2>0</slip2>
              </ode>
              <torsional>
                <coefficient>1</coefficient>
                <patch_radius>0</patch_radius>
                <surface_radius>0</surface_radius>
                <use_patch_radius>1</use_patch_radius>
                <ode>
                  <slip>0</slip>
                </ode>
              </torsional>
            </friction>
            <bounce>
              <restitution_coefficient>0</restitution_coefficient>
              <threshold>1e+06</threshold>
            </bounce>
            <contact>
              <collide_without_contact>0</collide_without_contact>
              <collide_without_contact_bitmask>1</collide_without_contact_bitmask>
              <collide_bitmask>1</collide_bitmask>
              <ode>
                <soft_cfm>0</soft_cfm>
                <soft_erp>0.2</soft_erp>
                <kp>1e+13</kp>
                <kd>1</kd>
                <max_vel>0.01</max_vel>
                <min_depth>0</min_depth>
              </ode>
              <bullet>
                <split_impulse>1</split_impulse>
                <split_impulse_penetration_threshold>-0.01</split_impulse_penetration_threshold>
                <soft_cfm>0</soft_cfm>
                <soft_erp>0.2</soft_erp>
                <kp>1e+13</kp>
                <kd>1</kd>
              </bullet>
            </contact>
          </surface>
        </collision>
      </link>
      <static>1</static>
      <allow_auto_disable>1</allow_auto_disable>
      <pose>2.52651 -0.638522 0 0 -0 0</pose>
    </model>
    <model name='Landing_pad'>
      <link name='link_0'>
        <inertial>
          <mass>1</mass>
          <inertia>
            <ixx>0.145833</ixx>
            <ixy>0</ixy>
            <ixz>0</ixz>
            <iyy>0.145833</iyy>
            <iyz>0</iyz>
            <izz>0.125</izz>
          </inertia>
          <pose>0 0 0 0 -0 0</pose>
        </inertial>
        <pose>0 0 0 0 -0 0</pose>
        <gravity>1</gravity>
        <self_collide>0</self_collide>
        <kinematic>0</kinematic>
        <enable_wind>0</enable_wind>
        <visual name='visual'>
          <pose>0 0 0 0 -0 0</pose>
          <geometry>
            <cylinder>
              <radius>0.305</radius>
              <length>0.025</length>
            </cylinder>
          </geometry>
          <material>
            <lighting>1</lighting>
            <script>
              <uri>file://media/materials/scripts/gazebo.material</uri>
              <name>Gazebo/Green</name>
            </script>
            <shader type='pixel'>
              <normal_map>__default__</normal_map>
            </shader>
            <ambient>0 1 0 1</ambient>
            <diffuse>0 1 0 1</diffuse>
            <specular>0 1 0 1</specular>
            <emissive>0 1 0 1</emissive>
          </material>
          <transparency>0</transparency>
          <cast_shadows>1</cast_shadows>
        </visual>
        <collision name='collision'>
          <laser_retro>0</laser_retro>
          <max_contacts>10</max_contacts>
          <pose>0 0 0 0 -0 0</pose>
          <geometry>
            <cylinder>
              <radius>0.305</radius>
              <length>0.025</length>
            </cylinder>
          </geometry>
          <surface>
            <friction>
              <ode>
                <mu>1</mu>
                <mu2>1</mu2>
                <fdir1>0 0 0</fdir1>
                <slip1>0</slip1>
                <slip2>0</slip2>
              </ode>
              <torsional>
                <coefficient>1</coefficient>
                <patch_radius>0</patch_radius>
                <surface_radius>0</surface_radius>
                <use_patch_radius>1</use_patch_radius>
                <ode>
                  <slip>0</slip>
                </ode>
              </torsional>
            </friction>
            <bounce>
              <restitution_coefficient>0</restitution_coefficient>
              <threshold>1e+06</threshold>
            </bounce>
            <contact>
              <collide_without_contact>0</collide_without_contact>
              <collide_without_contact_bitmask>1</collide_without_contact_bitmask>
              <collide_bitmask>1</collide_bitmask>
              <ode>
                <soft_cfm>0</soft_cfm>
                <soft_erp>0.2</soft_erp>
                <kp>1e+13</kp>
                <kd>1</kd>
                <max_vel>0.01</max_vel>
                <min_depth>0</min_depth>
              </ode>
              <bullet>
                <split_impulse>1</split_impulse>
                <split_impulse_penetration_threshold>-0.01</split_impulse_penetration_threshold>
                <soft_cfm>0</soft_cfm>
                <soft_erp>0.2</soft_erp>
                <kp>1e+13</kp>
                <kd>1</kd>
              </bullet>
            </contact>
          </surface>
        </collision>
      </link>
      <static>0</static>
      <allow_auto_disable>1</allow_auto_disable>
      <pose>3.00789 1.00753 0.012491 0 -0 0</pose>
    </model>
  </world>
</sdf>
